Workbook
Name CCG: INDIRECT("Reference!$H$2:$H$"&Reference!$I$2+1)
Name Chart1b: [1]Hip!#REF!
Name ColCat: OFFSET('[2]Column Chart'!$A$2,0,0,COUNTA('[2]Column Chart'!$A:$A)-1,1)
Name ColData: OFFSET('[2]Column Chart'!$B$2,0,0,COUNTA('[2]Column Chart'!$B:$B)-1,1)
Name ColStand: OFFSET('[2]Column Chart'!$C$2,0,0,COUNTA('[2]Column Chart'!$A:$A)-1,1)
Name DonutCat: OFFSET('[2]Donut & Pie'!$A$2,0,0,COUNTA('[2]Donut & Pie'!$A:$A)-1,1)
Name DonutData: OFFSET('[2]Donut & Pie'!$B$2,0,0,COUNTA('[2]Donut & Pie'!$A:$A)-1,1)
Name Funnel_Data: INDIRECT("'Provider Commission - Raw Data'!$A$1:$Q$"&ProvCommData!$B$61)
Name Funnel_Data: INDIRECT("'Provider Commission - Raw Data'!$A$1:$Q$"&'Chart data'!$B$47)
Name Funnel_Organisation_Level: INDIRECT("Reference!$AF$2:$AF$"&Reference!$AG$2+1)
Name HbarCat: OFFSET('[2]H Bar Chart'!$A$2,0,0,COUNTA('[2]H Bar Chart'!$A:$A)-1,1)
Name HbarData: OFFSET('[2]H Bar Chart'!$B$2,0,0,COUNTA('[2]H Bar Chart'!$A:$A)-1,1)
Name HBarStand: OFFSET('[2]H Bar Chart'!$C$2,0,0,COUNTA('[2]H Bar Chart'!$A:$A)-1,1)
Name HBarStandx: OFFSET('[2]H Bar Chart'!$C$2,0,0,COUNTA('[2]H Bar Chart'!$A:$A)-1,1)
Name HBarStandY: OFFSET('[2]H Bar Chart'!$D$2,0,0,COUNTA('[2]H Bar Chart'!$A:$A)-1,1)
Name KeyFacts_Organisation_Level: INDIRECT("Reference!$AC$2:$AC$"&Reference!$AD$2+1)
Name KeyFacts_RawData: INDIRECT("'Key Facts - Raw Data'!$A$1:$M$"&'Chart data'!$B$41)
Name MPTS_Data1: OFFSET('[2]Multi-series Line Chart'!$B$2,0,0,COUNTA('[2]Multi-series Line Chart'!$B:$B)-1,1)
Name MPTS_Data10: OFFSET('[2]Multi-series Line Chart'!$K$2,0,0,COUNTA('[2]Multi-series Line Chart'!$K:$K)-1,1)
Name MPTS_Data11: OFFSET('[2]Multi-series Line Chart'!$L$2,0,0,COUNTA('[2]Multi-series Line Chart'!$L:$L)-1,1)
Name MPTS_Data12: OFFSET('[2]Multi-series Line Chart'!$M$2,0,0,COUNTA('[2]Multi-series Line Chart'!$M:$M)-1,1)
Name MPTS_Data13: OFFSET('[2]Multi-series Line Chart'!$N$2,0,0,COUNTA('[2]Multi-series Line Chart'!$N:$N)-1,1)
Name MPTS_Data14: OFFSET('[2]Multi-series Line Chart'!$O$2,0,0,COUNTA('[2]Multi-series Line Chart'!$O:$O)-1,1)
Name MPTS_Data15: OFFSET('[2]Multi-series Line Chart'!$P$2,0,0,COUNTA('[2]Multi-series Line Chart'!$P:$P)-1,1)
Name MPTS_Data2: OFFSET('[2]Multi-series Line Chart'!$C$2,0,0,COUNTA('[2]Multi-series Line Chart'!$C:$C)-1,1)
Name MPTS_Data3: OFFSET('[2]Multi-series Line Chart'!$D$2,0,0,COUNTA('[2]Multi-series Line Chart'!$D:$D)-1,1)
Name MPTS_Data4: OFFSET('[2]Multi-series Line Chart'!$E$2,0,0,COUNTA('[2]Multi-series Line Chart'!$E:$E)-1,1)
Name MPTS_Data5: OFFSET('[2]Multi-series Line Chart'!$F$2,0,0,COUNTA('[2]Multi-series Line Chart'!$F:$F)-1,1)
Name MPTS_Data6: OFFSET('[2]Multi-series Line Chart'!$G$2,0,0,COUNTA('[2]Multi-series Line Chart'!$G:$G)-1,1)
Name MPTS_Data7: OFFSET('[2]Multi-series Line Chart'!$H$2,0,0,COUNTA('[2]Multi-series Line Chart'!$H:$H)-1,1)
Name MPTS_Data8: OFFSET('[2]Multi-series Line Chart'!$I$2,0,0,COUNTA('[2]Multi-series Line Chart'!$I:$I)-1,1)
Name MPTS_Data9: OFFSET('[2]Multi-series Line Chart'!$J$2,0,0,COUNTA('[2]Multi-series Line Chart'!$J:$J)-1,1)
Name MPTS_Period: OFFSET('[2]Multi-series Line Chart'!$A$2,0,0,COUNTA('[2]Multi-series Line Chart'!$A:$A)-1,1)
Name MPTSStand: OFFSET('[2]Multi-series Line Chart'!$Q$2,0,0,COUNTA('[2]Multi-series Line Chart'!$A:$A)-1,1)
Name Participation_Data: INDIRECT("'Participation - Raw Data'!$B$1:$Bm$"&ProvCommData!$B$58)
Name Participation_Data: INDIRECT("'Participation - Raw Data'!$B$1:$Bm$"&'Chart data'!$B$44)
Name PCTs: INDIRECT("Reference!$K$2:$K$"&Reference!$L$2+1)
Name Procedure_List: Reference!$Y$13:$Y$18
Name ProviderCommissionerNewChart: 'Provider Commission - NewChart'!$B$2:$Q$7585
Name Providers: INDIRECT("Reference!$E$2:$E$"&Reference!$F$2+1)
Name ScatItem: OFFSET([2]Scatterplot!$A$2,0,0,COUNTA([2]Scatterplot!$A:$A)-1,1)
Name ScatX: OFFSET([2]Scatterplot!$B$2,0,0,COUNTA([2]Scatterplot!$A:$A)-1,1)
Name ScatY: OFFSET([2]Scatterplot!$C$2,0,0,COUNTA([2]Scatterplot!$A:$A)-1,1)
Name ScatYG1: OFFSET([2]Scatterplot!$E$2,0,0,COUNTA([2]Scatterplot!$A:$A)-1,1)
Name ScatYG2: OFFSET([2]Scatterplot!$F$2,0,0,COUNTA([2]Scatterplot!$A:$A)-1,1)
Name ScatYG3: OFFSET([2]Scatterplot!$G$2,0,0,COUNTA([2]Scatterplot!$A:$A)-1,1)
Name ScatYG4: OFFSET([2]Scatterplot!$H$2,0,0,COUNTA([2]Scatterplot!$A:$A)-1,1)
Name SCTSData1: OFFSET('[2]Area Chart or Column'!$B$2,0,0,COUNTA('[2]Area Chart or Column'!$A:$A)-1,1)
Name SCTSData2: OFFSET('[2]Area Chart or Column'!$C$2,0,0,COUNTA('[2]Area Chart or Column'!$A:$A)-1,1)
Name SCTSData3: OFFSET('[2]Area Chart or Column'!$D$2,0,0,COUNTA('[2]Area Chart or Column'!$A:$A)-1,1)
Name SCTSPeriod: OFFSET('[2]Area Chart or Column'!$A$2,0,0,COUNTA('[2]Area Chart or Column'!$A:$A)-1,1)
Name SHAs: Reference!$N$2:$N$10
Name STSPeriod: OFFSET('[2]Stacked TS'!$A$2,0,0,COUNTA('[2]Stacked TS'!$A$1:$A$13)-1,1)
Name STSYear1: OFFSET('[2]Stacked TS'!$B$2,0,0,COUNTA('[2]Stacked TS'!$A$1:$A$13)-1,1)
Name STSYear2: OFFSET('[2]Stacked TS'!$C$2,0,0,COUNTA('[2]Stacked TS'!$A$1:$A$13)-1,1)
Name STSYear3: OFFSET('[2]Stacked TS'!$D$2,0,0,COUNTA('[2]Stacked TS'!$A$1:$A$13)-1,1)
Name STSYear4: OFFSET('[2]Stacked TS'!$E$2,0,0,COUNTA('[2]Stacked TS'!$A$1:$A$13)-1,1)
Name STSYear5: OFFSET('[2]Stacked TS'!#REF!,0,0,COUNTA('[2]Stacked TS'!$A$1:$A$13)-1,1)
Name STSYear6: OFFSET('[2]Stacked TS'!#REF!,0,0,COUNTA('[2]Stacked TS'!$A$1:$A$13)-1,1)
Name STSYear7: OFFSET('[2]Stacked TS'!#REF!,0,0,COUNTA('[2]Stacked TS'!$A$1:$A$13)-1,1)

Sheet How to use
A1: User guide for PROMs Score Comparison workbook
A3: Please note: | C3: 1 | E3: All cells with this colour code contain formula's - Do not change.
C4: 2 | D4: Named ranges - SHAs; PCTs; CCGs; Providers contain INDIRECT formulas which do not automatically update if columns are added or removed in the 'Reference' sheet. This should only be a factor during development and not quaterly updates.
C5: 3
C6: 4 | D6: Protection applied to individual sheets and the workbook structure is not password protected. Protection is use to facilitate usage not protect data.
C7: 5 | D7: Column F on this worksheet has been formated as a tick list - key lower case a to enter a tick.
A10: Quarterly updates | F10: Tick list
A12: 1 | B12: TAB | C12: Reference | E12: Update cells B2 - start of data range (month and year) for the Score Comparison (e.g. April 2011 for PROMs year 2011-12) | F12: a
E13: B3 - end of data range (month and year) for the Score Comparison (e.g. March 2012 for PROMs year 2011-12) | F13: a
E14: B4 - date (day month and year) this Score Comparison will be published (e.g.15th November 2013) | F14: a
E15: B5 - select true from the dropdown if this is a provisional data set and false if it is a finalised data set | F15: a
E16: B6 - date (day month and year) finalised data set is expected to be published. If this is a finalised data set put the date it will be published | F16: a
A18: 2 | B18: TAB | C18: Key Facts - Raw Data | E18: Get appropriate Key Facts CSV file from SharePoint (Key Facts folder under current publication number). Make sure - the Organisation names for Providers and CCGs have the organisation code in brackets after the name. - the lookup column is Organisation Type Organisation Name Procedure Measure concaternated with no additional spaces between the fields. - Check Orgnaisation Type, Organisation Name and Organisation Code are all ENGLAND and not National or ENG at England level. | F18: a
E19: Copy the new data set (without the column headings) and paste (use paste special - values and number formatting) into cell A2. Make a note of the last row number and check this is the number in cell B41 on the 'Chart data' tab. | F19: a
A21: 3 | B21: TAB | C21: Participation - Raw Data | E21: Get appropriate Participation and Linkage CSV file from SharePoint (Participation Rates folder under current publication number). Make sure - the Organisation names for Providers and CCGs have the organisation code in brackets after the name. - check Organisation Name and Organisation Code are both England and not National or ENG at England level. | F21: a
E22: Copy the new data set (without the column headings) and paste (use paste special - values and number formatting) into cell A2. Make a note of the last row number and check this is the number in cell B44 on the 'Chart data' tab. | F22: a
A24: 4 | B24: TAB | C24: Provider Commission - Raw Data | E24: Get appropriate Provider Commissioner CSV file from SharePoint (Provider Level folder under current publication number) - Make sure the Organisation names for Providers and CCGs have the organisation code in brackets after the name. | F24: a
E25: Sort by 'Procedure; Organisation Type; Measure; Organisation Name | F25: a
E26: N.B. Provider Commission - Raw Data, columns A and B contain formulas
E27: Copy the new data set (without the column headings) and paste (use paste special - values and number formatting) into cell C2 | F27: a
E28: Copy down the formulas columns A and B (cells containing formula's will be highlighted automatically). Make a note of the last row number and check this is the number in cell B47 on the 'Chart data' tab. | F28: a
E29: Repeat steps above for Provider Commission - New Chart'
A30: 5 | B30: TAB | C30: Funnel setup | E30: Run query QRY SCORE COMPARISON - FUNNEL SETUP from Code Library | F30: a
E31: This selects England level data for the specified year by Procedure and Measure for Modelled Records; Average Post-Op Q score; Adjusted Average Health Gain; Upper Control limit 99.8; Standard Deviation.
E32: Copy new data (without column headings) and paste (use paste special - values and number formatting) in cells B4. | F32: a
E34: Check Adjusted Average Health Gain and Upper Control Limit 99.8 have the same sign for Aberdeen Varicose Vein Questionnaire (+ or - doesn't matter which) | F34: a
A36: 6 | B36: TAB | C36: Reference | E36: Updated Columns E and H with the current CCG and Provider names from both Provider Commission - Raw Data and Participation - Raw data data sets. Make sure each name only appears once in each list and has the organisation code in brackets after the name. Sort each list alphabetically if there are any 'Unknown' place at the bottom of the list and not under 'U'. Check the number of organisations match those given on the 'Chart data' tab There are place holders for PCTs and SHAs which can be over typed with new organisational levels should the need arise. | F36: a
A38: 7 | B38: Finally | C38: Check all the 'Refers to' data in Named Ranges to ensure there are no #REF errors | F38: a
C39: Check there are no #N/A's in Chart Data
C40: Check the Score Comparison workbook is working properly e.g. drop down lists, dates, data etc.
C41: Check the Funnel Plot and Funnel Data worksheets are working properly e.g. drop down lists, dates, full data set included, no error messages etc.
C42: Check there are no error messages in Provider Commission - Lookup
A44: 8 | B44: Publication | C44: 1 | D44: Hide tabs in yellow
E45: How to use
E46: Reference
E47: Key Facts - Raw Data
E48: Participation - Raw Data
E49: Provider Commission - Raw Data
E50: Funnel setup
E51: Chart data
...

Sheet Participation - Raw Data
A1: Organisation Code | B1: Organisation Name - SC | C1: All Procedures - Total HES Procedures | D1: All Procedures - Total Pre-Op Qs | E1: All Procedures - Participation Rate | F1: All Procedures - Total Linked | G1: All Procedures - Linkage rate | H1: All Procedures - Total Q2s sent to date | I1: All Procedures - Issue rate | J1: All Procedures - Total Q2s returned to date | K1: All Procedures - Response rate | L1: Hip Replacement - Total HES Procedures | M1: Hip Replacement - Total Pre-Op Qs | N1: Hip Replacement - Participation Rate | O1: Hip Replacement - Total Linked | P1: Hip Replacement - Linkage rate | Q1: Hip Replacement - Total Q2s sent to date | R1: Hip Replacement - Issue rate | S1: Hip Replacement - Total Q2s returned to date | T1: Hip Replacement - Response rate | U1: Primary Hip Replacement - Total HES Procedures | V1: Primary Hip Replacement - Total Pre-Op Qs | W1: Primary Hip Replacement - Participation Rate | X1: Primary Hip Replacement - Total Linked | Y1: Primary Hip Replacement - Linkage rate | Z1: Primary Hip Replacement - Total Q2s sent to date | AA1: Primary Hip Replacement - Issue rate | AB1: Primary Hip Replacement - Total Q2s returned to date | AC1: Primary Hip Replacement - Response rate | AD1: Revision Hip Replacement - Total HES Procedures | AE1: Revision Hip Replacement - Total Pre-Op Qs | AF1: Revision Hip Replacement - Participation Rate | AG1: Revision Hip Replacement - Total Linked | AH1: Revision Hip Replacement - Linkage rate | AI1: Revision Hip Replacement - Total Q2s sent to date | AJ1: Revision Hip Replacement - Issue rate | AK1: Revision Hip Replacement - Total Q2s returned to date | AL1: Revision Hip Replacement - Response rate | AM1: Knee Replacement - Total HES Procedures | AN1: Knee Replacement - Total Pre-Op Qs | AO1: Knee Replacement - Participation Rate | AP1: Knee Replacement - Total Linked | AQ1: Knee Replacement - Linkage rate | AR1: Knee Replacement - Total Q2s sent to date | AS1: Knee Replacement - Issue rate | AT1: Knee Replacement - Total Q2s returned to date | AU1: Knee Replacement - Response rate | AV1: Primary Knee Replacement - Total HES Procedures | AW1: Primary Knee Replacement - Total Pre-Op Qs | AX1: Primary Knee Replacement - Participation Rate | AY1: Primary Knee Replacement - Total Linked | AZ1: Primary Knee Replacement - Linkage rate | BA1: Primary Knee Replacement - Total Q2s sent to date | BB1: Primary Knee Replacement - Issue rate | BC1: Primary Knee Replacement - Total Q2s returned to date | BD1: Primary Knee Replacement - Response rate | BE1: Revision Knee Replacement - Total HES Procedures | BF1: Revision Knee Replacement - Total Pre-Op Qs | BG1: Revision Knee Replacement - Participation Rate | BH1: Revision Knee Replacement - Total Linked | BI1: Revision Knee Replacement - Linkage rate | BJ1: Revision Knee Replacement - Total Q2s sent to date | BK1: Revision Knee Replacement - Issue rate | BL1: Revision Knee Replacement - Total Q2s returned to date | BM1: Revision Knee Replacement - Response rate

Sheet Provider Commission - Raw Data
A1: . | B1: Lookup | C1: Procedure | D1: Organisation Type | E1: Organisation Code | F1: Organisation Name | G1: Measure | H1: Modelled Records | I1: Average Pre-Op Q Score | J1: Average Post-Op Q Score | K1: Health Gain | L1: Improved | M1: Same | N1: Worse | O1: Adjusted Post-Op Q Score | P1: Adjusted Average Health Gain | Q1: Standard Deviation
A2: =IF(C2&G2&D2<>'Funnel setup'!$K$3&'Funnel setup'!$K$4&'Funnel setup'!$K$6,".",IF(A1=".",1,A1+1)) -> . | B2: =C2&D2&F2&G2
A3: =IF(C3&G3&D3<>'Funnel setup'!$K$3&'Funnel setup'!$K$4&'Funnel setup'!$K$6,".",IF(A2=".",1,A2+1)) -> . | B3: =C3&D3&F3&G3
A4: =IF(C4&G4&D4<>'Funnel setup'!$K$3&'Funnel setup'!$K$4&'Funnel setup'!$K$6,".",IF(A3=".",1,A3+1)) -> . | B4: =C4&D4&F4&G4
A5: =IF(C5&G5&D5<>'Funnel setup'!$K$3&'Funnel setup'!$K$4&'Funnel setup'!$K$6,".",IF(A4=".",1,A4+1)) -> . | B5: =C5&D5&F5&G5
A6: =IF(C6&G6&D6<>'Funnel setup'!$K$3&'Funnel setup'!$K$4&'Funnel setup'!$K$6,".",IF(A5=".",1,A5+1)) -> . | B6: =C6&D6&F6&G6
A7: =IF(C7&G7&D7<>'Funnel setup'!$K$3&'Funnel setup'!$K$4&'Funnel setup'!$K$6,".",IF(A6=".",1,A6+1)) -> . | B7: =C7&D7&F7&G7
A8: =IF(C8&G8&D8<>'Funnel setup'!$K$3&'Funnel setup'!$K$4&'Funnel setup'!$K$6,".",IF(A7=".",1,A7+1)) -> . | B8: =C8&D8&F8&G8
A9: =IF(C9&G9&D9<>'Funnel setup'!$K$3&'Funnel setup'!$K$4&'Funnel setup'!$K$6,".",IF(A8=".",1,A8+1)) -> . | B9: =C9&D9&F9&G9
A10: =IF(C10&G10&D10<>'Funnel setup'!$K$3&'Funnel setup'!$K$4&'Funnel setup'!$K$6,".",IF(A9=".",1,A9+1)) -> . | B10: =C10&D10&F10&G10
A11: =IF(C11&G11&D11<>'Funnel setup'!$K$3&'Funnel setup'!$K$4&'Funnel setup'!$K$6,".",IF(A10=".",1,A10+1)) -> . | B11: =C11&D11&F11&G11
A12: =IF(C12&G12&D12<>'Funnel setup'!$K$3&'Funnel setup'!$K$4&'Funnel setup'!$K$6,".",IF(A11=".",1,A11+1)) -> . | B12: =C12&D12&F12&G12
A13: =IF(C13&G13&D13<>'Funnel setup'!$K$3&'Funnel setup'!$K$4&'Funnel setup'!$K$6,".",IF(A12=".",1,A12+1)) -> . | B13: =C13&D13&F13&G13
... A7768: =IF(C7768&G7768&D7768<>'Funnel setup'!$K$3&'Funnel setup'!$K$4&'Funnel setup'!$K$6,".",IF(A7767=".",1,A7767+1)) -> . | B7768: =C7768&D7768&F7768&G7768

Sheet Provider Commission - NewChart
A1: . | B1: Lookup | C1: Procedure | D1: Organisation Type | E1: Organisation Code | F1: Organisation Name | G1: Measure | H1: Modelled Records | I1: Average Pre-Op Q Score | J1: Average Post-Op Q Score | K1: Health Gain | L1: Improved | M1: Same | N1: Worse | O1: Adjusted Post-Op Q Score | P1: Adjusted Average Health Gain | Q1: Standard Deviation
A2: =IF(C2&G2&D2<>'Funnel setup'!$K$3&'Funnel setup'!$K$4&'Funnel setup'!$K$6,".",IF(A1=".",1,A1+1)) -> . | B2: =C2&D2&F2&G2
A3: =IF(C3&G3&D3<>'Funnel setup'!$K$3&'Funnel setup'!$K$4&'Funnel setup'!$K$6,".",IF(A2=".",1,A2+1)) -> . | B3: =C3&D3&F3&G3
A4: =IF(C4&G4&D4<>'Funnel setup'!$K$3&'Funnel setup'!$K$4&'Funnel setup'!$K$6,".",IF(A3=".",1,A3+1)) -> . | B4: =C4&D4&F4&G4
A5: =IF(C5&G5&D5<>'Funnel setup'!$K$3&'Funnel setup'!$K$4&'Funnel setup'!$K$6,".",IF(A4=".",1,A4+1)) -> . | B5: =C5&D5&F5&G5
A6: =IF(C6&G6&D6<>'Funnel setup'!$K$3&'Funnel setup'!$K$4&'Funnel setup'!$K$6,".",IF(A5=".",1,A5+1)) -> . | B6: =C6&D6&F6&G6
A7: =IF(C7&G7&D7<>'Funnel setup'!$K$3&'Funnel setup'!$K$4&'Funnel setup'!$K$6,".",IF(A6=".",1,A6+1)) -> . | B7: =C7&D7&F7&G7
A8: =IF(C8&G8&D8<>'Funnel setup'!$K$3&'Funnel setup'!$K$4&'Funnel setup'!$K$6,".",IF(A7=".",1,A7+1)) -> . | B8: =C8&D8&F8&G8
A9: =IF(C9&G9&D9<>'Funnel setup'!$K$3&'Funnel setup'!$K$4&'Funnel setup'!$K$6,".",IF(A8=".",1,A8+1)) -> . | B9: =C9&D9&F9&G9
A10: =IF(C10&G10&D10<>'Funnel setup'!$K$3&'Funnel setup'!$K$4&'Funnel setup'!$K$6,".",IF(A9=".",1,A9+1)) -> . | B10: =C10&D10&F10&G10
A11: =IF(C11&G11&D11<>'Funnel setup'!$K$3&'Funnel setup'!$K$4&'Funnel setup'!$K$6,".",IF(A10=".",1,A10+1)) -> . | B11: =C11&D11&F11&G11
A12: =IF(C12&G12&D12<>'Funnel setup'!$K$3&'Funnel setup'!$K$4&'Funnel setup'!$K$6,".",IF(A11=".",1,A11+1)) -> . | B12: =C12&D12&F12&G12
A13: =IF(C13&G13&D13<>'Funnel setup'!$K$3&'Funnel setup'!$K$4&'Funnel setup'!$K$6,".",IF(A12=".",1,A12+1)) -> . | B13: =C13&D13&F13&G13
... A7768: =IF(C7768&G7768&D7768<>'Funnel setup'!$K$3&'Funnel setup'!$K$4&'Funnel setup'!$K$6,".",IF(A7767=".",1,A7767+1)) -> . | B7768: =C7768&D7768&F7768&G7768

Sheet Funnel setup
B1: Data from dbo.AJW_Aggregated_Stats for Funnel Plot (Model2 for GH and VV; Model 3 for HR and KR)
A3: Lookup | B3: Procedure | C3: Measure | D3: Modelled Records | E3: Average Post-Op Q Score | F3: Adjusted Average Health Gain | G3: Upper Control Limit 99.8 | H3: Standard Deviation | J3: Procedure | K3: ='Funnel Plot'!B11 -> Total Hip Replacement
A4: =B4&C4 | J4: Measure | K4: ='Funnel Plot'!D11 -> Oxford Hip Score
A5: =B5&C5
A6: =B6&C6 | J6: Organisation Type | K6: ='Funnel Plot'!F11 -> Provider
A7: =B7&C7 | J7: Organisation Name | K7: ='Funnel Plot'!H11 -> BLACKPOOL TEACHING HOSPITALS NHS FOUNDATION TRUST (RXL)
A8: =B8&C8 | J8: Standard Deviation | K8: =VLOOKUP(K3&K4,A:H,8,0) -> #N/A
A9: =B9&C9 | J9: Mean (Adjusted Average Health Gain) | K9: =VLOOKUP(K3&K4,A:H,6,0) -> #N/A
A10: =B10&C10 | J10: Selected (n) | K10: =VLOOKUP(K3&K6&K7&K4,'Provider Commission - Raw Data'!B:Q,7,0) -> #N/A
A11: =B11&C11 | J11: Number of records (n) | K11: =MAX('Provider Commission - Raw Data'!A:A) -> 0
A12: =B12&C12 | J12: MIN (n) | K12: 10
A13: =B13&C13 | J13: MAX (n) | K13: {=CEILING(MAX(IF(ISERROR('Funnel Lookup'!S3:S403),50,'Funnel Lookup'!S3:S403)),50)} -> 50
A14: =B14&C14 | J14: Funnel Increment | K14: =EXP((LN(K13)-LN(K12))/19) -> 1.0883984
A15: =B15&C15 | K15: =IF(K4="Aberdeen Varicose Vein Questionnaire","Lower ","Upper ") -> Upper
A16: =B16&C16 | K16: =IF(K4="Aberdeen Varicose Vein Questionnaire","Upper ","Lower ") -> Lower
A17: =B17&C17 | J17: Funnel Plot - Image1
A18: =B18&C18 | J18: Funnel Plot - Image2
A19: =B19&C19
A20: =B20&C20
A21: =B21&C21 | K21: 95% control limits | L21: Upper 95% control limit | M21: 99.8% control limits | N21: Upper 99.8% control limit | O21: England | P21: Funnel Data
J22: x | K22: lower 2 sigma | L22: upper 2 sigma | M22: lower 3 sigma | N22: upper 3 sigma | O22: mean | P22: table key
J23: 10 | K23: =$K$9-(2*$K$8)/SQRT(J23) -> #N/A | L23: =$K$9+(2*$K$8)/SQRT(J23) -> #N/A | M23: =$K$9-(3*$K$8)/SQRT(J23) -> #N/A | N23: =$K$9+(3*$K$8)/SQRT(J23) -> #N/A | O23: =$K$9 -> #N/A | P23: 1
J24: =J23*K$14 -> 10.883984 | K24: =$K$9-(2*$K$8)/SQRT(J24) -> #N/A | L24: =$K$9+(2*$K$8)/SQRT(J24) -> #N/A | M24: =$K$9-(3*$K$8)/SQRT(J24) -> #N/A | N24: =$K$9+(3*$K$8)/SQRT(J24) -> #N/A | O24: =$K$9 -> #N/A | P24: =IF(P23="","",IF(P23+1>'Funnel setup'!$K$11,"",P23+1))
J25: =J24*K$14 -> 11.846111 | K25: =$K$9-(2*$K$8)/SQRT(J25) -> #N/A | L25: =$K$9+(2*$K$8)/SQRT(J25) -> #N/A | M25: =$K$9-(3*$K$8)/SQRT(J25) -> #N/A | N25: =$K$9+(3*$K$8)/SQRT(J25) -> #N/A | O25: =$K$9 -> #N/A | P25: =IF(P24="","",IF(P24+1>'Funnel setup'!$K$11,"",P24+1))
J26: =J25*K$14 -> 12.893288 | K26: =$K$9-(2*$K$8)/SQRT(J26) -> #N/A | L26: =$K$9+(2*$K$8)/SQRT(J26) -> #N/A | M26: =$K$9-(3*$K$8)/SQRT(J26) -> #N/A | N26: =$K$9+(3*$K$8)/SQRT(J26) -> #N/A | O26: =$K$9 -> #N/A | P26: =IF(P25="","",IF(P25+1>'Funnel setup'!$K$11,"",P25+1))
J27: =J26*K$14 -> 14.033034 | K27: =$K$9-(2*$K$8)/SQRT(J27) -> #N/A | L27: =$K$9+(2*$K$8)/SQRT(J27) -> #N/A | M27: =$K$9-(3*$K$8)/SQRT(J27) -> #N/A | N27: =$K$9+(3*$K$8)/SQRT(J27) -> #N/A | O27: =$K$9 -> #N/A | P27: =IF(P26="","",IF(P26+1>'Funnel setup'!$K$11,"",P26+1))
J28: =J27*K$14 -> 15.273532 | K28: =$K$9-(2*$K$8)/SQRT(J28) -> #N/A | L28: =$K$9+(2*$K$8)/SQRT(J28) -> #N/A | M28: =$K$9-(3*$K$8)/SQRT(J28) -> #N/A | N28: =$K$9+(3*$K$8)/SQRT(J28) -> #N/A | O28: =$K$9 -> #N/A | P28: =IF(P27="","",IF(P27+1>'Funnel setup'!$K$11,"",P27+1))
J29: =J28*K$14 -> 16.623688 | K29: =$K$9-(2*$K$8)/SQRT(J29) -> #N/A | L29: =$K$9+(2*$K$8)/SQRT(J29) -> #N/A | M29: =$K$9-(3*$K$8)/SQRT(J29) -> #N/A | N29: =$K$9+(3*$K$8)/SQRT(J29) -> #N/A | O29: =$K$9 -> #N/A | P29: =IF(P28="","",IF(P28+1>'Funnel setup'!$K$11,"",P28+1))
J30: =J29*K$14 -> 18.093195 | K30: =$K$9-(2*$K$8)/SQRT(J30) -> #N/A | L30: =$K$9+(2*$K$8)/SQRT(J30) -> #N/A | M30: =$K$9-(3*$K$8)/SQRT(J30) -> #N/A | N30: =$K$9+(3*$K$8)/SQRT(J30) -> #N/A | O30: =$K$9 -> #N/A | P30: =IF(P29="","",IF(P29+1>'Funnel setup'!$K$11,"",P29+1))
J31: =J30*K$14 -> 19.692605 | K31: =$K$9-(2*$K$8)/SQRT(J31) -> #N/A | L31: =$K$9+(2*$K$8)/SQRT(J31) -> #N/A | M31: =$K$9-(3*$K$8)/SQRT(J31) -> #N/A | N31: =$K$9+(3*$K$8)/SQRT(J31) -> #N/A | O31: =$K$9 -> #N/A | P31: =IF(P30="","",IF(P30+1>'Funnel setup'!$K$11,"",P30+1))
J32: =J31*K$14 -> 21.433399 | K32: =$K$9-(2*$K$8)/SQRT(J32) -> #N/A | L32: =$K$9+(2*$K$8)/SQRT(J32) -> #N/A | M32: =$K$9-(3*$K$8)/SQRT(J32) -> #N/A | N32: =$K$9+(3*$K$8)/SQRT(J32) -> #N/A | O32: =$K$9 -> #N/A | P32: =IF(P31="","",IF(P31+1>'Funnel setup'!$K$11,"",P31+1))
J33: =J32*K$14 -> 23.328078 | K33: =$K$9-(2*$K$8)/SQRT(J33) -> #N/A | L33: =$K$9+(2*$K$8)/SQRT(J33) -> #N/A | M33: =$K$9-(3*$K$8)/SQRT(J33) -> #N/A | N33: =$K$9+(3*$K$8)/SQRT(J33) -> #N/A | O33: =$K$9 -> #N/A | P33: =IF(P32="","",IF(P32+1>'Funnel setup'!$K$11,"",P32+1))
J34: =J33*K$14 -> 25.390242 | K34: =$K$9-(2*$K$8)/SQRT(J34) -> #N/A | L34: =$K$9+(2*$K$8)/SQRT(J34) -> #N/A | M34: =$K$9-(3*$K$8)/SQRT(J34) -> #N/A | N34: =$K$9+(3*$K$8)/SQRT(J34) -> #N/A | O34: =$K$9 -> #N/A | P34: =IF(P33="","",IF(P33+1>'Funnel setup'!$K$11,"",P33+1))
J35: =J34*K$14 -> 27.634699 | K35: =$K$9-(2*$K$8)/SQRT(J35) -> #N/A | L35: =$K$9+(2*$K$8)/SQRT(J35) -> #N/A | M35: =$K$9-(3*$K$8)/SQRT(J35) -> #N/A | N35: =$K$9+(3*$K$8)/SQRT(J35) -> #N/A | O35: =$K$9 -> #N/A | P35: =IF(P34="","",IF(P34+1>'Funnel setup'!$K$11,"",P34+1))
... J42: =J41*K$14 -> 50 | K42: =$K$9-(2*$K$8)/SQRT(J42) -> #N/A | L42: =$K$9+(2*$K$8)/SQRT(J42) -> #N/A | M42: =$K$9-(3*$K$8)/SQRT(J42) -> #N/A | N42: =$K$9+(3*$K$8)/SQRT(J42) -> #N/A | O42: =$K$9 -> #N/A | P42: =IF(P41="","",IF(P41+1>'Funnel setup'!$K$11,"",P41+1))
P43: =IF(P42="","",IF(P42+1>'Funnel setup'!$K$11,"",P42+1))
P44: =IF(P43="","",IF(P43+1>'Funnel setup'!$K$11,"",P43+1))
P45: =IF(P44="","",IF(P44+1>'Funnel setup'!$K$11,"",P44+1))
P46: =IF(P45="","",IF(P45+1>'Funnel setup'!$K$11,"",P45+1))
P47: =IF(P46="","",IF(P46+1>'Funnel setup'!$K$11,"",P46+1))
...

Sheet Reference
A1: Update dates for each new publication | B1: Date ranges for Publication Title | E1: Provider | F1: Number of Providers | H1: CCG | I1: Number of CCGs | K1: PCT | L1: Number of PCTs | N1: SHA | O1: No of SHAs | Q1: National | R1: No of National | U1: HR measures | V1: No of Measures for Funnel_Score | W1: No of Measures for Select 10 Table | Y1: Unadjusted Procedures | AA1: Organisation Level This column feeds these definitions in formulas - amend here to amend formulas, inc named ranges | AC1: Organisation Level (dropdown) | AD1: Number of Org level | AF1: Organisation Type - Funnel Plot | AG1: No of Org Types
A2: Data range from (mmmm yyyy) | F2: =COUNTA(E:E)-1 -> 0 | I2: =COUNTA(H:H)-1 -> 0 | K2: England | L2: =COUNTA(K:K)-1 -> 1 | N2: England | O2: =COUNTA(N:N)-1 -> 1 | Q2: England | R2: 1 | U2: EQ-5D Index | V2: =IF('Funnel Plot'!B11="Groin Hernia",2,3) -> 3 | W2: =IF('Select 10 table'!B13="Groin Hernia",2,3) -> 3 | Y2: Total Hip Replacement | AA2: England | AC2: England | AD2: =COUNTA(AC:AC)-1 -> 3 | AF2: CCG of GP Practice | AG2: =COUNTA(AF:AF)-1 -> 2
A3: Data range to (mmmm yyyy) | U3: EQ VAS | Y3: Hip Replacement Primary | AA3: SHA of responsibility | AC3: CCG of GP Practice | AF3: Provider
A4: Published on (dd mmmm yyyy) | U4: Oxford Hip Score | Y4: Hip Replacement Revision | AA4: PCT of responsibility | AC4: Provider
A5: Provisional publication (TRUE/FALSE)? | C5: q | Y5: Total Knee Replacement | AA5: CCG of GP Practice
A6: When finalised publication expected? (dd mmmm yyyy) | U6: HR split measures | Y6: Knee Replacement Primary | AA6: Provider
U7: EQ-5D Index | Y7: Knee Replacement Revision
A8: Publication Link | U8: EQ VAS
U9: Oxford Hip Score
A10: Link for copyright statement
A11: ="Copyright © "&YEAR(NOW())&", Health and Social Care Information Centre. The Health and Social Care Information Centre is a non-departmental body created by statute, also known as NHS Digital." -> Copyright © 2023, Health and Social Care Information Centre. The Health and Social Care Information Centre is a non-departmental body created by statute, also known as NHS Digital. | U11: KR Measures
U12: EQ-5D Index | Y12: Case-Mix Adjusted Procedures
U13: EQ VAS | Y13: Total Hip Replacement
U14: Oxford Knee Score | Y14: Hip Replacement Primary
Y15: Hip Replacement Revision
U16: KR split measures | Y16: Total Knee Replacement
U17: EQ-5D Index | Y17: Knee Replacement Primary
U18: EQ VAS | Y18: Knee Replacement Revision
U19: Oxford Knee Score

Sheet Supplier_Note
A1: Provider | B1: Note
A2: AIREDALE NHS FOUNDATION TRUST (RCF)
A3: ALDER HEY CHILDREN'S NHS FOUNDATION TRUST (RBS)
A4: ASHFORD AND ST PETER'S HOSPITALS NHS FOUNDATION TRUST (RTK)
A5: ASHTEAD HOSPITAL (NVC01)
A6: ASPEN - CLAREMONT HOSPITAL (NYW04)
A7: ASPEN - HIGHGATE HOSPITAL (NYW03)
A8: ASPEN - PARKSIDE HOSPITAL (NYW02)
A9: ASPEN - THE HOLLY (NYW01)
A10: BARKING, HAVERING AND REDBRIDGE UNIVERSITY HOSPITALS NHS TRUST (RF4) | B10: 3. The participation rate for this supplier may be affected by a change in supplier, please see the "Accredited Supplier Switchover" note on the Title Sheet for more details.
A11: BARLBOROUGH NHS TREATMENT CENTRE (NTP13)
A12: BARNSLEY HOSPITAL NHS FOUNDATION TRUST (RFF)
A13: BARTS HEALTH NHS TRUST (R1H)
A14: BASILDON AND THURROCK UNIVERSITY HOSPITALS NHS FOUNDATION TRUST (RDD)
A15: BEDFORD HOSPITAL NHS TRUST (RC1)
A16: BENENDEN HOSPITAL (NWF01)
A17: BICS-COMMUNITY (NWX11)
A18: BIRMINGHAM WOMEN'S AND CHILDREN'S NHS FOUNDATION TRUST (RQ3)
A19: BLACKPOOL TEACHING HOSPITALS NHS FOUNDATION TRUST (RXL)
A20: BMI - BATH CLINIC (NT402)
A21: BMI - BISHOPS WOOD (NT405)
A22: BMI - CHELSFIELD PARK HOSPITAL (NT409)
... A89: EMERSONS GREEN NHS TREATMENT CENTRE (NTPH2)
A90: EPSOM AND ST HELIER UNIVERSITY HOSPITALS NHS TRUST (RVR) | B90: 3. The participation rate for this supplier may be affected by a change in supplier, please see the "Accredited Supplier Switchover" note on the Title Sheet for more details.
A91: EUXTON HALL HOSPITAL (NVC05)
A92: FAIRFIELD HOSPITAL (NVG01)
A93: FITZWILLIAM HOSPITAL (NVC06)
A94: FOSCOTE COURT (BANBURY) TRUST LTD (AHH)
A95: FRIMLEY HEALTH NHS FOUNDATION TRUST (RDU)
A96: FULWOOD HALL HOSPITAL (NVC07)
A97: GATESHEAD HEALTH NHS FOUNDATION TRUST (RR7)
A98: GEORGE ELIOT HOSPITAL NHS TRUST (RLT)
A99: GLOUCESTERSHIRE HOSPITALS NHS FOUNDATION TRUST (RTE)
A100: GREAT WESTERN HOSPITALS NHS FOUNDATION TRUST (RN3)
A101: GUY'S AND ST THOMAS' NHS FOUNDATION TRUST (RJ1) | B101: 3. The participation rate for this supplier may be affected by a change in supplier, please see the "Accredited Supplier Switchover" note on the Title Sheet for more details.
A102: HAMPSHIRE HOSPITALS NHS FOUNDATION TRUST (RN5)
A103: HARROGATE AND DISTRICT NHS FOUNDATION TRUST (RCD)
A104: HOMERTON UNIVERSITY HOSPITAL NHS FOUNDATION TRUST (RQX)
A105: HORTON NHS TREATMENT CENTRE (NVC25)
A106: HULL UNIVERSITY TEACHING HOSPITALS NHS TRUST (RWA)
...

Sheet ProvCommData
A1: Key Facts
A3: Organisation validation | B3: =IF('Adjusted Health Gain Chart'!D11=Reference!AA2,VLOOKUP('Adjusted Health Gain Chart'!$B$11,Reference!$Q$2,1,FALSE),IF('Adjusted Health Gain Chart'!B11=Reference!AA3,VLOOKUP('Adjusted Health Gain Chart'!D11,SHAs,1,FALSE),IF('Adjusted Health Gain Chart'!B11=Reference!AA4,VLOOKUP('Adjusted Health Gain Chart'!D11,PCTs,1,FALSE),IF('Adjusted Health Gain Chart'!B11=Reference!AA5,VLOOKUP('Adjusted Health Gain Chart'!D11,CCG,1,FALSE),VLOOKUP('Adjusted Health Gain Chart'!D11,Providers,1,FALSE))))) -> #N/A | F3: **If there is an #N/A here check the formulas for Named ranges 'SHAs', 'PCTs', 'CCGs','Providers' as the INDIRECT formula will not update automatically if there is movement in the columns on the 'Reference' sheet
A4: No of Organisations | B4: =IF('Adjusted Health Gain Chart'!B11=Reference!AA2,Reference!R2,IF('Adjusted Health Gain Chart'!B11=Reference!AA3,Reference!O2,IF('Adjusted Health Gain Chart'!B11=Reference!AA4,Reference!L2,IF('Adjusted Health Gain Chart'!B11=Reference!AA5,Reference!I2,IF('Adjusted Health Gain Chart'!B11=Reference!AA6,Reference!F2))))) -> 0
A6: Organisation level | B6: ='Adjusted Health Gain Chart'!B11 -> Provider
A7: Organisation name | B7: ='Adjusted Health Gain Chart'!D11 -> BARKING, HAVERING AND REDBRIDGE UNIVERSITY HOSPITALS NHS TRUST (RF4)
A8: Lookup | B8: =B6&B7 -> ProviderBARKING, HAVERING AND REDBRIDGE UNIVERSITY HOSPITALS NHS TRUST (RF4)
A11: Horizontal Axis | C11: Adjusted average health gain | D11: Adjusted average health gain (England) | E11: Y values | F11: Modelled records | G11: England modelled records | I11: y increments= no. categories +1 / no. categories | K11: Y series
B12: ="Knee - revision " &"("&F12 &")" -> Knee - revision (0) | C12: =IF(ISNA(VLOOKUP(Reference!$Y$18&$B$8&Reference!$U$14,ProviderCommissionerNewChart,15,FALSE)),"No data",IF(VLOOKUP(Reference!$Y$18&$B$8&Reference!$U$14,ProviderCommissionerNewChart,15,FALSE)="-","No data",VLOOKUP(Reference!$Y$18&$B$8&Reference!$U$14,ProviderCommissionerNewChart,15,FALSE))) -> No data | D12: =IF(G12>=200,(VLOOKUP(Reference!$Y$18&Reference!$AA$2&Reference!$AA$2&Reference!$U$14,ProviderCommissionerNewChart,15,FALSE)),"Insufficient data") -> #N/A | E12: 0.455 | F12: =IF(ISNA(VLOOKUP(Reference!$Y$18&$B$8&Reference!$U$14,ProviderCommissionerNewChart,7,FALSE)),0,(VLOOKUP(Reference!$Y$18&$B$8&Reference!$U$14,ProviderCommissionerNewChart,7,FALSE))) -> 0 | G12: =VLOOKUP(Reference!$Y$18&Reference!$AA$2&Reference!$AA$2&Reference!$U$14,ProviderCommissionerNewChart,7,FALSE) -> #N/A | H12: OHS / OKS | I12: =9/10 -> 0.9 | J12: =I12/2 -> 0.45 | K12: =J12 -> 0.45
B13: ="Knee - primary " &"("&F13 &")" -> Knee - primary (0) | C13: =IF(ISNA(VLOOKUP(Reference!$Y$17&$B$8&Reference!$U$14,ProviderCommissionerNewChart,15,FALSE)),"No data",IF(VLOOKUP(Reference!$Y$17&$B$8&Reference!$U$14,ProviderCommissionerNewChart,15,FALSE)="-","No data",VLOOKUP(Reference!$Y$17&$B$8&Reference!$U$14,ProviderCommissionerNewChart,15,FALSE))) -> No data | D13: =IF(G13>=200,(VLOOKUP(Reference!$Y$17&Reference!$AA$2&Reference!$AA$2&Reference!$U$14,ProviderCommissionerNewChart,15,FALSE)),"Insufficient data") -> #N/A | E13: 1.35 | F13: =IF(ISNA(VLOOKUP(Reference!$Y$17&$B$8&Reference!$U$14,ProviderCommissionerNewChart,7,FALSE)),0,(VLOOKUP(Reference!$Y$17&$B$8&Reference!$U$14,ProviderCommissionerNewChart,7,FALSE))) -> 0 | G13: =VLOOKUP(Reference!$Y$17&Reference!$AA$2&Reference!$AA$2&Reference!$U$14,ProviderCommissionerNewChart,7,FALSE) -> #N/A | K13: =K12+$I$12 -> 1.35
B14: ="Total Knee Replacment " &"("&F14 &")" -> Total Knee Replacment (0) | C14: =IF(ISNA(VLOOKUP(Reference!$Y$16&$B$8&Reference!$U$14,ProviderCommissionerNewChart,15,FALSE)),"No data",IF(VLOOKUP(Reference!$Y$16&$B$8&Reference!$U$14,ProviderCommissionerNewChart,15,FALSE)="-","No data",VLOOKUP(Reference!$Y$16&$B$8&Reference!$U$14,ProviderCommissionerNewChart,15,FALSE))) -> No data | D14: =IF(G14>=200,(VLOOKUP(Reference!$Y$16&Reference!$AA$2&Reference!$AA$2&Reference!$U$14,ProviderCommissionerNewChart,15,FALSE)),"Insufficient data") -> #N/A | E14: =E13+0.9 -> 2.25 | F14: =IF(ISNA(VLOOKUP(Reference!$Y$16&$B$8&Reference!$U$14,ProviderCommissionerNewChart,7,FALSE)),0,(VLOOKUP(Reference!$Y$16&$B$8&Reference!$U$14,ProviderCommissionerNewChart,7,FALSE))) -> 0 | G14: =VLOOKUP(Reference!$Y$16&Reference!$AA$2&Reference!$AA$2&Reference!$U$14,ProviderCommissionerNewChart,7,FALSE) -> #N/A | K14: =K13+$I$12 -> 2.25
B15: ="Oxford Knee Score " -> Oxford Knee Score | E15: 3.13 | H15: min EQ-5D | K15: =K14+$I$12 -> 3.15
E16: 4 | H16: max EQ-5D | K16: =K15+$I$12 -> 4.05
B17: ="Hip - revision " &"("&F17 &")" -> Hip - revision (0) | C17: =IF(ISNA(VLOOKUP(Reference!$Y$15&$B$8&Reference!$U$9,ProviderCommissionerNewChart,15,FALSE)),"No data",IF(VLOOKUP(Reference!$Y$15&$B$8&Reference!$U$9,ProviderCommissionerNewChart,15,FALSE)="-","No data",VLOOKUP(Reference!$Y$15&$B$8&Reference!$U$9,ProviderCommissionerNewChart,15,FALSE))) -> No data | D17: =IF(G17>=200,(VLOOKUP(Reference!$Y$15&Reference!$AA$2&Reference!$AA$2&Reference!$U$9,ProviderCommissionerNewChart,15,FALSE)),"Insufficient data") -> #N/A | E17: =E16+0.9 -> 4.9 | F17: =IF(ISNA(VLOOKUP(Reference!$Y$15&$B$8&Reference!$U$9,ProviderCommissionerNewChart,7,FALSE)),0,(VLOOKUP(Reference!$Y$15&$B$8&Reference!$U$9,ProviderCommissionerNewChart,7,FALSE))) -> 0 | G17: =VLOOKUP(Reference!$Y$15&Reference!$AA$2&Reference!$AA$2&Reference!$U$9,ProviderCommissionerNewChart,7,FALSE) -> #N/A | H17: min EQ Vas | K17: =K16+$I$12 -> 4.95
B18: ="Hip - primary " &"("&F18 &")" -> Hip - primary (0) | C18: =IF(ISNA(VLOOKUP(Reference!$Y$14&$B$8&Reference!$U$9,ProviderCommissionerNewChart,15,FALSE)),"No data",IF(VLOOKUP(Reference!$Y$14&$B$8&Reference!$U$9,ProviderCommissionerNewChart,15,FALSE)="-","No data",VLOOKUP(Reference!$Y$14&$B$8&Reference!$U$9,ProviderCommissionerNewChart,15,FALSE))) -> No data | D18: =IF(G18>=200,(VLOOKUP(Reference!$Y$14&Reference!$AA$2&Reference!$AA$2&Reference!$U$9,ProviderCommissionerNewChart,15,FALSE)),"Insufficient data") -> #N/A | E18: =E17+0.9 -> 5.8 | F18: =IF(ISNA(VLOOKUP(Reference!$Y$14&$B$8&Reference!$U$9,ProviderCommissionerNewChart,7,FALSE)),0,(VLOOKUP(Reference!$Y$14&$B$8&Reference!$U$9,ProviderCommissionerNewChart,7,FALSE))) -> 0 | G18: =VLOOKUP(Reference!$Y$14&Reference!$AA$2&Reference!$AA$2&Reference!$U$9,ProviderCommissionerNewChart,7,FALSE) -> #N/A | H18: max EQ Vas | K18: =K17+$I$12 -> 5.85
B19: ="Total Hip Replacment " &"("&F19 &")" -> Total Hip Replacment (0) | C19: =IF(ISNA(VLOOKUP(Reference!$Y$13&$B$8&Reference!$U$9,ProviderCommissionerNewChart,15,FALSE)),"No data",IF(VLOOKUP(Reference!$Y$13&$B$8&Reference!$U$9,ProviderCommissionerNewChart,15,FALSE)="-","No data",VLOOKUP(Reference!$Y$13&$B$8&Reference!$U$9,ProviderCommissionerNewChart,15,FALSE))) -> No data | D19: =IF(G19>=200,(VLOOKUP(Reference!$Y$13&Reference!$AA$2&Reference!$AA$2&Reference!$U$9,ProviderCommissionerNewChart,15,FALSE)),"Insufficient data") -> #N/A | E19: =E18+0.9 -> 6.7 | F19: =IF(ISNA(VLOOKUP(Reference!$Y$13&$B$8&Reference!$U$9,ProviderCommissionerNewChart,7,FALSE)),0,(VLOOKUP(Reference!$Y$13&$B$8&Reference!$U$9,ProviderCommissionerNewChart,7,FALSE))) -> 0 | G19: =VLOOKUP(Reference!$Y$13&Reference!$AA$2&Reference!$AA$2&Reference!$U$9,ProviderCommissionerNewChart,7,FALSE) -> #N/A | K19: =K18+$I$12 -> 6.75
B20: Oxford Hip Score | H20: Min OKS/OHS | K20: =K19+$I$12 -> 7.65
H21: Max OKS/OHS | K21: =K20+$I$12 -> 8.55
B22: ="Knee revision " &"("&F22 &")" -> Knee revision (0) | C22: =IF(ISNA(VLOOKUP(Reference!$Y$18&$B$8&Reference!$U$13,ProviderCommissionerNewChart,15,FALSE)),"No data",IF(VLOOKUP(Reference!$Y$18&$B$8&Reference!$U$13,ProviderCommissionerNewChart,15,FALSE)="-","No data",VLOOKUP(Reference!$Y$18&$B$8&Reference!$U$13,ProviderCommissionerNewChart,15,FALSE))) -> No data | D22: =IF(G22>=200,(VLOOKUP(Reference!$Y$18&Reference!$AA$2&Reference!$AA$2&Reference!$U$13,ProviderCommissionerNewChart,15,FALSE)),"Insufficient data") -> #N/A | E22: 0.6 | F22: =IF(ISNA(VLOOKUP(Reference!$Y$18&$B$8&Reference!$U$13,ProviderCommissionerNewChart,7,FALSE)),0,(VLOOKUP(Reference!$Y$18&$B$8&Reference!$U$13,ProviderCommissionerNewChart,7,FALSE))) -> 0 | G22: =VLOOKUP(Reference!$Y$18&Reference!$AA$2&Reference!$AA$2&Reference!$U$13,ProviderCommissionerNewChart,7,FALSE) -> #N/A | H22: Min AVVQ | K22: =K21+$I$12 -> 9.45 | M22: =(Reference!$Y$18&Reference!$AA$2&Reference!$AA$2&Reference!$U$13) -> Knee Replacement RevisionEnglandEnglandEQ VAS
B23: ="Knee - primary " &"("&F23 &")" -> Knee - primary (0) | C23: =IF(ISNA(VLOOKUP(Reference!$Y$17&$B$8&Reference!$U$13,ProviderCommissionerNewChart,15,FALSE)),"No data",IF(VLOOKUP(Reference!$Y$17&$B$8&Reference!$U$13,ProviderCommissionerNewChart,15,FALSE)="-","No data",VLOOKUP(Reference!$Y$17&$B$8&Reference!$U$13,ProviderCommissionerNewChart,15,FALSE))) -> No data | D23: =IF(G24>=200,(VLOOKUP(Reference!$Y$17&Reference!$AA$2&Reference!$AA$2&Reference!$U$13,ProviderCommissionerNewChart,15,FALSE)),"Insufficient data") -> #N/A | E23: =E22+1.15 -> 1.75 | F23: =IF(ISNA(VLOOKUP(Reference!$Y$17&$B$8&Reference!$U$13,ProviderCommissionerNewChart,7,FALSE)),0,(VLOOKUP(Reference!$Y$17&$B$8&Reference!$U$13,ProviderCommissionerNewChart,7,FALSE))) -> 0 | G23: =VLOOKUP(Reference!$Y$17&Reference!$AA$2&Reference!$AA$2&Reference!$U$13,ProviderCommissionerNewChart,7,FALSE) -> #N/A | H23: Max AVVQ | K23: =K22+$I$12 -> 10.35
B24: ="Total Knee Replacement " &"("&F24 &")" -> Total Knee Replacement (0) | C24: =IF(ISNA(VLOOKUP(Reference!$Y$16&$B$8&Reference!$U$13,ProviderCommissionerNewChart,15,FALSE)),"No data",IF(VLOOKUP(Reference!$Y$16&$B$8&Reference!$U$13,ProviderCommissionerNewChart,15,FALSE)="-","No data",VLOOKUP(Reference!$Y$16&$B$8&Reference!$U$13,ProviderCommissionerNewChart,15,FALSE))) -> No data | D24: =IF(G24>=200,(VLOOKUP(Reference!$Y$16&Reference!$AA$2&Reference!$AA$2&Reference!$U$13,ProviderCommissionerNewChart,15,FALSE)),"Insufficient data") -> #N/A | E24: =E23+1.15 -> 2.9 | F24: =IF(ISNA(VLOOKUP(Reference!$Y$16&$B$8&Reference!$U$13,ProviderCommissionerNewChart,7,FALSE)),0,(VLOOKUP(Reference!$Y$16&$B$8&Reference!$U$13,ProviderCommissionerNewChart,7,FALSE))) -> 0 | G24: =VLOOKUP(Reference!$Y$16&Reference!$AA$2&Reference!$AA$2&Reference!$U$13,ProviderCommissionerNewChart,7,FALSE) -> #N/A | K24: =K23+$I$12 -> 11.25
B25: ="Hip - revision " &"("&F25 &")" -> Hip - revision (0) | C25: =IF(ISNA(VLOOKUP(Reference!$Y$15&$B$8&Reference!$U$3,ProviderCommissionerNewChart,15,FALSE)),"No data",IF(VLOOKUP(Reference!$Y$15&$B$8&Reference!$U$3,ProviderCommissionerNewChart,15,FALSE)="-","No data",VLOOKUP(Reference!$Y$15&$B$8&Reference!$U$3,ProviderCommissionerNewChart,15,FALSE))) -> No data | D25: =IF(G25>=200,(VLOOKUP(Reference!$Y$15&Reference!$AA$2&Reference!$AA$2&Reference!$U$3,ProviderCommissionerNewChart,15,FALSE)),"Insufficient data") -> #N/A | E25: =E24+1.2 -> 4.1 | F25: =IF(ISNA(VLOOKUP(Reference!$Y$15&$B$8&Reference!$U$3,ProviderCommissionerNewChart,7,FALSE)),0,(VLOOKUP(Reference!$Y$15&$B$8&Reference!$U$3,ProviderCommissionerNewChart,7,FALSE))) -> 0 | G25: =VLOOKUP(Reference!$Y$15&Reference!$AA$2&Reference!$AA$2&Reference!$U$3,ProviderCommissionerNewChart,7,FALSE) -> #N/A | K25: =K24+$I$12 -> 12.15
B26: ="Hip - primary " &"("&F26 &")" -> Hip - primary (0) | C26: =IF(ISNA(VLOOKUP(Reference!$Y$14&$B$8&Reference!$U$3,ProviderCommissionerNewChart,15,FALSE)),"No data",IF(VLOOKUP(Reference!$Y$14&$B$8&Reference!$U$3,ProviderCommissionerNewChart,15,FALSE)="-","No data",VLOOKUP(Reference!$Y$14&$B$8&Reference!$U$3,ProviderCommissionerNewChart,15,FALSE))) -> No data | D26: =IF(G26>=200,(VLOOKUP(Reference!$Y$14&Reference!$AA$2&Reference!$AA$2&Reference!$U$3,ProviderCommissionerNewChart,15,FALSE)),"Insufficient data") -> #N/A | E26: =E25+1.15 -> 5.25 | F26: =IF(ISNA(VLOOKUP(Reference!$Y$14&$B$8&Reference!$U$3,ProviderCommissionerNewChart,7,FALSE)),0,(VLOOKUP(Reference!$Y$14&$B$8&Reference!$U$3,ProviderCommissionerNewChart,7,FALSE))) -> 0 | G26: =VLOOKUP(Reference!$Y$14&Reference!$AA$2&Reference!$AA$2&Reference!$U$3,ProviderCommissionerNewChart,7,FALSE) -> #N/A | K26: =K25+$I$12 -> 13.05
B27: ="Total Hip Replacement " &"("&F27 &")" -> Total Hip Replacement (0) | C27: =IF(ISNA(VLOOKUP(Reference!$Y$13&$B$8&Reference!$U$3,ProviderCommissionerNewChart,15,FALSE)),"No data",IF(VLOOKUP(Reference!$Y$13&$B$8&Reference!$U$3,ProviderCommissionerNewChart,15,FALSE)="-","No data",VLOOKUP(Reference!$Y$13&$B$8&Reference!$U$3,ProviderCommissionerNewChart,15,FALSE))) -> No data | D27: =IF(G27>=200,(VLOOKUP(Reference!$Y$13&Reference!$AA$2&Reference!$AA$2&Reference!$U$3,ProviderCommissionerNewChart,15,FALSE)),"Insufficient data") -> #N/A | E27: =E26+1.2 -> 6.45 | F27: =IF(ISNA(VLOOKUP(Reference!$Y$13&$B$8&Reference!$U$3,ProviderCommissionerNewChart,7,FALSE)),0,(VLOOKUP(Reference!$Y$13&$B$8&Reference!$U$3,ProviderCommissionerNewChart,7,FALSE))) -> 0 | G27: =VLOOKUP(Reference!$Y$13&Reference!$AA$2&Reference!$AA$2&Reference!$U$3,ProviderCommissionerNewChart,7,FALSE) -> #N/A | J27: useful formula | K27: =K26+$I$12 -> 13.95
B28: EQ VAS | J28: =IF($G$31>=200,(VLOOKUP(Reference!$Y$18&Reference!$AA$2&Reference!$AA$2&Reference!$U$2,ProviderCommissionerNewChart,15,FALSE)),0) -> #N/A | K28: =K27+$I$12 -> 14.85
K29: =K28+$I$12 -> 15.75
A30: ="Figure 1: Average adjusted health gain on the EQ-5D A17 Index by procedure, "&'Adjusted Health Gain Chart'!D11& " compared with England" -> Figure 1: Average adjusted health gain on the EQ-5D A17 Index by procedure, BARKING, HAVERING AND REDBRIDGE UNIVERSITY HOSPITALS NHS TRUST (RF4) compared with England | B30: ="Knee - revision " &"("&F30 &")" -> Knee - revision (0) | C30: =IF(ISNA(VLOOKUP(Reference!$Y$18&$B$8&Reference!$U$2,ProviderCommissionerNewChart,15,FALSE)),"No data",IF(VLOOKUP(Reference!$Y$18&$B$8&Reference!$U$2,ProviderCommissionerNewChart,15,FALSE)="-","No data",VLOOKUP(Reference!$Y$18&$B$8&Reference!$U$2,ProviderCommissionerNewChart,15,FALSE))) -> No data | D30: =IF(G30>=200,(VLOOKUP(Reference!$Y$18&Reference!$AA$2&Reference!$AA$2&Reference!$U$2,ProviderCommissionerNewChart,15,FALSE)),"Insufficient data") -> #N/A | E30: 0.6 | F30: =IF(ISNA(VLOOKUP(Reference!$Y$18&$B$8&Reference!$U$2,ProviderCommissionerNewChart,7,FALSE)),0,(VLOOKUP(Reference!$Y$18&$B$8&Reference!$U$2,ProviderCommissionerNewChart,7,FALSE))) -> 0 | G30: =VLOOKUP(Reference!$Y$18&Reference!$AA$2&Reference!$AA$2&Reference!$U$2,ProviderCommissionerNewChart,7,FALSE) -> #N/A | K30: =K29+$I$12 -> 16.65
B31: ="Knee - primary " &"("&F31 &")" -> Knee - primary (0) | C31: =IF(ISNA(VLOOKUP(Reference!$Y$17&$B$8&Reference!$U$2,ProviderCommissionerNewChart,15,FALSE)),"No data",IF(VLOOKUP(Reference!$Y$17&$B$8&Reference!$U$2,ProviderCommissionerNewChart,15,FALSE)="-","No data",VLOOKUP(Reference!$Y$17&$B$8&Reference!$U$2,ProviderCommissionerNewChart,15,FALSE))) -> No data | D31: =IF(G32>=200,(VLOOKUP(Reference!$Y$17&Reference!$AA$2&Reference!$AA$2&Reference!$U$2,ProviderCommissionerNewChart,15,FALSE)),"Insufficient data") -> #N/A | E31: =E30+1.15 -> 1.75 | F31: =IF(ISNA(VLOOKUP(Reference!$Y$17&$B$8&Reference!$U$2,ProviderCommissionerNewChart,7,FALSE)),0,(VLOOKUP(Reference!$Y$17&$B$8&Reference!$U$2,ProviderCommissionerNewChart,7,FALSE))) -> 0 | G31: =VLOOKUP(Reference!$Y$17&Reference!$AA$2&Reference!$AA$2&Reference!$U$2,ProviderCommissionerNewChart,7,FALSE) -> #N/A | K31: =K30+$I$12 -> 17.55
B32: ="Total Knee Replacment " &"("&F32 &")" -> Total Knee Replacment (0) | C32: =IF(ISNA(VLOOKUP(Reference!$Y$16&$B$8&Reference!$U$2,ProviderCommissionerNewChart,15,FALSE)), "No data",IF(VLOOKUP(Reference!$Y$16&$B$8&Reference!$U$2,ProviderCommissionerNewChart,15,FALSE)="-","No data",VLOOKUP(Reference!$Y$16&$B$8&Reference!$U$2,ProviderCommissionerNewChart,15,FALSE))) -> No data | D32: =IF(G32>=200,(VLOOKUP(Reference!$Y$16&Reference!$AA$2&Reference!$AA$2&Reference!$U$2,ProviderCommissionerNewChart,15,FALSE)),"Insufficient data") -> #N/A | E32: =E31+1.15 -> 2.9 | F32: =IF(ISNA(VLOOKUP(Reference!$Y$16&$B$8&Reference!$U$2,ProviderCommissionerNewChart,7,FALSE)),0,(VLOOKUP(Reference!$Y$16&$B$8&Reference!$U$2,ProviderCommissionerNewChart,7,FALSE))) -> 0 | G32: =VLOOKUP(Reference!$Y$16&Reference!$AA$2&Reference!$AA$2&Reference!$U$2,ProviderCommissionerNewChart,7,FALSE) -> #N/A | K32: =K31+$I$12 -> 18.45
B33: ="Hip - revision " &"("&F33 &")" -> Hip - revision (0) | C33: =IF(ISNA(VLOOKUP(Reference!$Y$15&$B$8&Reference!$U$2,ProviderCommissionerNewChart,15,FALSE)),"No data",IF(VLOOKUP(Reference!$Y$15&$B$8&Reference!$U$2,ProviderCommissionerNewChart,15,FALSE)="-","No data",VLOOKUP(Reference!$Y$15&$B$8&Reference!$U$2,ProviderCommissionerNewChart,15,FALSE))) -> No data | D33: =IF(G33>=200,(VLOOKUP(Reference!$Y$15&Reference!$AA$2&Reference!$AA$2&Reference!$U$2,ProviderCommissionerNewChart,15,FALSE)),"Insufficient data") -> #N/A | E33: =E32+1.2 -> 4.1 | F33: =IF(ISNA(VLOOKUP(Reference!$Y$15&$B$8&Reference!$U$2,ProviderCommissionerNewChart,7,FALSE)),0,(VLOOKUP(Reference!$Y$15&$B$8&Reference!$U$2,ProviderCommissionerNewChart,7,FALSE))) -> 0 | G33: =VLOOKUP(Reference!$Y$15&Reference!$AA$2&Reference!$AA$2&Reference!$U$2,ProviderCommissionerNewChart,7,FALSE) -> #N/A | K33: =K32+$I$12 -> 19.35
B34: ="Hip - primary " &"("&F34 &")" -> Hip - primary (0) | C34: =IF(ISNA(VLOOKUP(Reference!$Y$14&$B$8&Reference!$U$2,ProviderCommissionerNewChart,15,FALSE)),"No data",IF(VLOOKUP(Reference!$Y$14&$B$8&Reference!$U$2,ProviderCommissionerNewChart,15,FALSE)="-","No data",VLOOKUP(Reference!$Y$14&$B$8&Reference!$U$2,ProviderCommissionerNewChart,15,FALSE))) -> No data | D34: =IF(G34>=200,(VLOOKUP(Reference!$Y$14&Reference!$AA$2&Reference!$AA$2&Reference!$U$2,ProviderCommissionerNewChart,15,FALSE)),"Insufficient data") -> #N/A | E34: =E33+1.15 -> 5.25 | F34: =IF(ISNA(VLOOKUP(Reference!$Y$14&$B$8&Reference!$U$2,ProviderCommissionerNewChart,7,FALSE)),0,(VLOOKUP(Reference!$Y$14&$B$8&Reference!$U$2,ProviderCommissionerNewChart,7,FALSE))) -> 0 | G34: =VLOOKUP(Reference!$Y$14&Reference!$AA$2&Reference!$AA$2&Reference!$U$2,ProviderCommissionerNewChart,7,FALSE) -> #N/A | K34: =K33+$I$12 -> 20.25
B35: ="Total Hip Replacement " &"("&F35 &")" -> Total Hip Replacement (0) | C35: =IF(ISNA(VLOOKUP(Reference!$Y$13&$B$8&Reference!$U$2,ProviderCommissionerNewChart,15,FALSE)),"No data",IF(VLOOKUP(Reference!$Y$13&$B$8&Reference!$U$2,ProviderCommissionerNewChart,15,FALSE)="-","No data",VLOOKUP(Reference!$Y$13&$B$8&Reference!$U$2,ProviderCommissionerNewChart,15,FALSE))) -> No data | D35: =IF(G35>=200,(VLOOKUP(Reference!$Y$13&Reference!$AA$2&Reference!$AA$2&Reference!$U$2,ProviderCommissionerNewChart,15,FALSE)),"Insufficient data") -> #N/A | E35: =E34+1.2 -> 6.45 | F35: =IF(ISNA(VLOOKUP(Reference!$Y$13&$B$8&Reference!$U$2,ProviderCommissionerNewChart,7,FALSE)),0,(VLOOKUP(Reference!$Y$13&$B$8&Reference!$U$2,ProviderCommissionerNewChart,7,FALSE))) -> 0 | G35: =VLOOKUP(Reference!$Y$13&Reference!$AA$2&Reference!$AA$2&Reference!$U$2,ProviderCommissionerNewChart,7,FALSE) -> #N/A | K35: =K34+$I$12 -> 21.15
B36: EQ-5D Index
A39: Pre-operative participation and linkage | C39: Eligible Procedures | D39: Pre-operative questionnaires completed | E39: Participation Rate | F39: Pre-operative questionnaires linked | G39: Linkage Rate
A40: Procedure | B40: All Procedures | C40: =VLOOKUP("England",Participation_Data,2,FALSE) -> #N/A | D40: =VLOOKUP("England",Participation_Data,3,FALSE) -> #N/A | E40: =VLOOKUP("England",Participation_Data,4,FALSE) -> #N/A | F40: =VLOOKUP("England",Participation_Data,5,FALSE) -> #N/A | G40: =VLOOKUP("England",Participation_Data,6,FALSE) -> #N/A
B41: Groin Hernia | C41: =VLOOKUP("England",Participation_Data,11,FALSE) -> #N/A | D41: =VLOOKUP("England",Participation_Data,12,FALSE) -> #N/A | E41: =VLOOKUP("England",Participation_Data,13,FALSE) -> #N/A | F41: =VLOOKUP("England",Participation_Data,14,FALSE) -> #N/A | G41: =VLOOKUP("England",Participation_Data,15,FALSE) -> #N/A
B42: Hip Replacement | C42: =VLOOKUP("England",Participation_Data,20,FALSE) -> #N/A | D42: =VLOOKUP("England",Participation_Data,21,FALSE) -> #N/A | E42: =VLOOKUP("England",Participation_Data,22,FALSE) -> #N/A | F42: =VLOOKUP("England",Participation_Data,23,FALSE) -> #N/A | G42: =VLOOKUP("England",Participation_Data,24,FALSE) -> #N/A
B43: Knee Replacement | C43: =VLOOKUP("England",Participation_Data,29,FALSE) -> #N/A | D43: =VLOOKUP("England",Participation_Data,30,FALSE) -> #N/A | E43: =VLOOKUP("England",Participation_Data,31,FALSE) -> #N/A | F43: =VLOOKUP("England",Participation_Data,32,FALSE) -> #N/A | G43: =VLOOKUP("England",Participation_Data,33,FALSE) -> #N/A
B44: Varicose Vein | C44: =VLOOKUP("England",Participation_Data,38,FALSE) -> #N/A | D44: =VLOOKUP("England",Participation_Data,39,FALSE) -> #N/A | E44: =VLOOKUP("England",Participation_Data,40,FALSE) -> #N/A | F44: =VLOOKUP("England",Participation_Data,41,FALSE) -> #N/A | G44: =VLOOKUP("England",Participation_Data,42,FALSE) -> #N/A
A46: Post-operative issue and return | C46: Pre-operative questionnaires completed | D46: Post-operative questionnaires sent out | E46: Issue Rate | F46: Post-operative questionnaires returned | G46: Response Rate
A47: Procedure | B47: All Procedures | C47: =VLOOKUP("England",Participation_Data,3,FALSE) -> #N/A | D47: =VLOOKUP("England",Participation_Data,7,FALSE) -> #N/A | E47: =VLOOKUP("England",Participation_Data,8,FALSE) -> #N/A | F47: =VLOOKUP("England",Participation_Data,9,FALSE) -> #N/A | G47: =VLOOKUP("England",Participation_Data,10,FALSE) -> #N/A
...

Sheet Chart data
A1: Key Facts
A3: Organisation validation | B3: =IF(#REF!=Reference!AA2,VLOOKUP(#REF!,Reference!$Q$2,1,FALSE),IF(#REF!=Reference!AA3,VLOOKUP(#REF!,SHAs,1,FALSE),IF(#REF!=Reference!AA4,VLOOKUP(#REF!,PCTs,1,FALSE),IF(#REF!=Reference!AA5,VLOOKUP(#REF!,CCG,1,FALSE),VLOOKUP(#REF!,Providers,1,FALSE))))) -> #REF! | F3: **If there is an #N/A here check the formulas for Named ranges 'SHAs', 'PCTs', 'CCGs','Providers' as the INDIRECT formula will not update automatically if there is movement in the columns on the 'Reference' sheet
A4: No of Organisations | B4: =IF(#REF!=Reference!AA2,Reference!R2,IF(#REF!=Reference!AA3,Reference!O2,IF(#REF!=Reference!AA4,Reference!L2,IF(#REF!=Reference!AA5,Reference!I2,IF(#REF!=Reference!AA6,Reference!F2))))) -> #REF!
A6: Organisation level | B6: =#REF! -> #REF!
A7: Organisation name | B7: =#REF! -> #REF!
A8: Lookup | B8: =B6&B7 -> #REF!
A11: Horizontal Axis | C11: % Improved | D11: % Worse | E11: % England Improved | F11: % England Worse | G11: Y values | H11: Number Improved | I11: Number Worse
A12: Varicose Vein | B12: Aberdeen Varicose Vein Questionnaire | C12: =IF(ISNA(VLOOKUP($B$8&$A12&$B12,KeyFacts_RawData,11,FALSE)),"No data",VLOOKUP($B$8&$A12&$B12,KeyFacts_RawData,11,FALSE)) -> #REF! | D12: =IF(ISNA(VLOOKUP($B$8&$A12&$B12,KeyFacts_RawData,13,FALSE)),"No data",IF(ISNUMBER(VLOOKUP($B$8&$A12&$B12,KeyFacts_RawData,13,FALSE)),-VLOOKUP($B$8&$A12&$B12,KeyFacts_RawData,13,FALSE),VLOOKUP($B$8&$A12&$B12,KeyFacts_RawData,13,FALSE))) -> #REF! | E12: =IF(ISNA(VLOOKUP(Reference!$AA$2&Reference!$AA$2&$A$12&B12,KeyFacts_RawData,11,FALSE)),"No data",IF(VLOOKUP(Reference!$AA$2&Reference!$AA$2&$A$12&B12,KeyFacts_RawData,11,FALSE)="*",NA(),VLOOKUP(Reference!$AA$2&Reference!$AA$2&$A$12&B12,KeyFacts_RawData,11,FALSE))) -> #REF! | F12: =IF(ISNA(VLOOKUP(Reference!$AA$2&Reference!$AA$2&$A$12&$B12,KeyFacts_RawData,13,FALSE)),"No data",IF(VLOOKUP(Reference!$AA$2&Reference!$AA$2&$A$12&$B12,KeyFacts_RawData,13,FALSE) = "*",NA(),IF(ISNUMBER(VLOOKUP(Reference!$AA$2&Reference!$AA$2&$A$12&$B12,KeyFacts_RawData,13,FALSE)),-VLOOKUP(Reference!$AA$2&Reference!$AA$2&$A$12&$B12,KeyFacts_RawData,13,FALSE),VLOOKUP(Reference!$AA$2&Reference!$AA$2&$A$12&$B12,KeyFacts_RawData,13,FALSE)))) -> #REF! | G12: 0.5 | H12: =IF(ISNA(VLOOKUP($B$8&$A12&$B12,KeyFacts_RawData,7,FALSE)),"No data",VLOOKUP($B$8&$A12&$B12,KeyFacts_RawData,7,FALSE)) -> #REF! | I12: =IF(ISNA(VLOOKUP($B$8&$A12&$B12,KeyFacts_RawData,9,FALSE)),"No data",VLOOKUP($B$8&$A12&$B12,KeyFacts_RawData,9,FALSE)) -> #REF!
B13: EQ VAS | C13: =IF(ISNA(VLOOKUP($B$8&$A12&$B13,KeyFacts_RawData,11,FALSE)),"No data",VLOOKUP($B$8&$A12&$B13,KeyFacts_RawData,11,FALSE)) -> #REF! | D13: =IF(ISNA(VLOOKUP($B$8&$A12&$B13,KeyFacts_RawData,13,FALSE)),"No data",IF(ISNUMBER(VLOOKUP($B$8&$A12&$B13,KeyFacts_RawData,13,FALSE)),-VLOOKUP($B$8&$A12&$B13,KeyFacts_RawData,13,FALSE),VLOOKUP($B$8&$A12&$B13,KeyFacts_RawData,13,FALSE))) -> #REF! | E13: =IF(ISNA(VLOOKUP(Reference!$AA$2&Reference!$AA$2&$A$12&B13,KeyFacts_RawData,11,FALSE)),"No data",IF(VLOOKUP(Reference!$AA$2&Reference!$AA$2&$A$12&B13,KeyFacts_RawData,11,FALSE)="*",NA(),VLOOKUP(Reference!$AA$2&Reference!$AA$2&$A$12&B13,KeyFacts_RawData,11,FALSE))) -> #REF! | F13: =IF(ISNA(VLOOKUP(Reference!$AA$2&Reference!$AA$2&$A$12&$B13,KeyFacts_RawData,13,FALSE)),"No data",IF(VLOOKUP(Reference!$AA$2&Reference!$AA$2&$A$12&$B13,KeyFacts_RawData,13,FALSE) = "*",NA(),IF(ISNUMBER(VLOOKUP(Reference!$AA$2&Reference!$AA$2&$A$12&$B13,KeyFacts_RawData,13,FALSE)),-VLOOKUP(Reference!$AA$2&Reference!$AA$2&$A$12&$B13,KeyFacts_RawData,13,FALSE),VLOOKUP(Reference!$AA$2&Reference!$AA$2&$A$12&$B13,KeyFacts_RawData,13,FALSE)))) -> #REF! | G13: 1.5 | H13: =IF(ISNA(VLOOKUP($B$8&$A12&$B13,KeyFacts_RawData,7,FALSE)),"No data",VLOOKUP($B$8&$A12&$B13,KeyFacts_RawData,7,FALSE)) -> #REF! | I13: =IF(ISNA(VLOOKUP($B$8&$A12&$B13,KeyFacts_RawData,9,FALSE)),"No data",VLOOKUP($B$8&$A12&$B13,KeyFacts_RawData,9,FALSE)) -> #REF!
B14: EQ-5D Index | C14: =IF(ISNA(VLOOKUP('Chart data'!$B$8&$A12&$B14,KeyFacts_RawData,11,FALSE)),"No data",VLOOKUP('Chart data'!$B$8&$A12&$B14,KeyFacts_RawData,11,FALSE)) -> #REF! | D14: =IF(ISNA(VLOOKUP('Chart data'!$B$8&$A12&$B14,KeyFacts_RawData,13,FALSE)),"No data",IF(ISNUMBER(VLOOKUP('Chart data'!$B$8&$A12&$B14,KeyFacts_RawData,13,FALSE)),-VLOOKUP('Chart data'!$B$8&$A12&$B14,KeyFacts_RawData,13,FALSE),VLOOKUP('Chart data'!$B$8&$A12&$B14,KeyFacts_RawData,13,FALSE))) -> #REF! | E14: =IF(ISNA(VLOOKUP(Reference!$AA$2&Reference!$AA$2&$A$12&B14,KeyFacts_RawData,11,FALSE)),"No data",IF(VLOOKUP(Reference!$AA$2&Reference!$AA$2&$A$12&B14,KeyFacts_RawData,11,FALSE)="*",NA(),VLOOKUP(Reference!$AA$2&Reference!$AA$2&$A$12&B14,KeyFacts_RawData,11,FALSE))) -> #REF! | F14: =IF(ISNA(VLOOKUP(Reference!$AA$2&Reference!$AA$2&$A$12&$B14,KeyFacts_RawData,13,FALSE)),"No data",IF(VLOOKUP(Reference!$AA$2&Reference!$AA$2&$A$12&$B14,KeyFacts_RawData,13,FALSE) = "*",NA(),IF(ISNUMBER(VLOOKUP(Reference!$AA$2&Reference!$AA$2&$A$12&$B14,KeyFacts_RawData,13,FALSE)),-VLOOKUP(Reference!$AA$2&Reference!$AA$2&$A$12&$B14,KeyFacts_RawData,13,FALSE),VLOOKUP(Reference!$AA$2&Reference!$AA$2&$A$12&$B14,KeyFacts_RawData,13,FALSE)))) -> #REF! | G14: 2.5 | H14: =IF(ISNA(VLOOKUP('Chart data'!$B$8&$A12&$B14,KeyFacts_RawData,7,FALSE)),"No data",VLOOKUP('Chart data'!$B$8&$A12&$B14,KeyFacts_RawData,7,FALSE)) -> #REF! | I14: =IF(ISNA(VLOOKUP('Chart data'!$B$8&$A12&$B14,KeyFacts_RawData,9,FALSE)),"No data",VLOOKUP('Chart data'!$B$8&$A12&$B14,KeyFacts_RawData,9,FALSE)) -> #REF!
A15: Knee Replacement | B15: Oxford Knee Score | C15: =IF(ISNA(VLOOKUP($B$8&A15&B15,KeyFacts_RawData,11,FALSE)),"No data",VLOOKUP($B$8&A15&B15,KeyFacts_RawData,11,FALSE)) -> #REF! | D15: =IF(ISNA(VLOOKUP($B$8&$A15&$B15,KeyFacts_RawData,13,FALSE)),"No data",IF(ISNUMBER(VLOOKUP($B$8&$A15&$B15,KeyFacts_RawData,13,FALSE)),-VLOOKUP($B$8&$A15&$B15,KeyFacts_RawData,13,FALSE),VLOOKUP($B$8&$A15&$B15,KeyFacts_RawData,13,FALSE))) -> #REF! | E15: =IF(ISNA(VLOOKUP(Reference!$AA$2&Reference!$AA$2&$A$15&B15,KeyFacts_RawData,11,FALSE)),"No data",IF(VLOOKUP(Reference!$AA$2&Reference!$AA$2&$A$15&B15,KeyFacts_RawData,11,FALSE)="*",NA(),VLOOKUP(Reference!$AA$2&Reference!$AA$2&$A$15&B15,KeyFacts_RawData,11,FALSE))) -> #REF! | F15: =IF(ISNA(VLOOKUP(Reference!$AA$2&Reference!$AA$2&$A$15&$B15,KeyFacts_RawData,13,FALSE)),"No data",IF(VLOOKUP(Reference!$AA$2&Reference!$AA$2&$A$15&$B15,KeyFacts_RawData,13,FALSE) = "*",NA(),IF(ISNUMBER(VLOOKUP(Reference!$AA$2&Reference!$AA$2&$A$15&$B15,KeyFacts_RawData,13,FALSE)),-VLOOKUP(Reference!$AA$2&Reference!$AA$2&$A$15&$B15,KeyFacts_RawData,13,FALSE),VLOOKUP(Reference!$AA$2&Reference!$AA$2&$A$15&$B15,KeyFacts_RawData,13,FALSE)))) -> #REF! | G15: 3.5 | H15: =IF(ISNA(VLOOKUP($B$8&$A15&$B15,KeyFacts_RawData,7,FALSE)),"No data",VLOOKUP($B$8&$A15&$B15,KeyFacts_RawData,7,FALSE)) -> #REF! | I15: =IF(ISNA(VLOOKUP($B$8&$A15&$B15,KeyFacts_RawData,9,FALSE)),"No data",VLOOKUP($B$8&$A15&$B15,KeyFacts_RawData,9,FALSE)) -> #REF!
B16: EQ VAS | C16: =IF(ISNA(VLOOKUP($B$8&A15&B16,KeyFacts_RawData,11,FALSE)),"No data",VLOOKUP($B$8&A15&B16,KeyFacts_RawData,11,FALSE)) -> #REF! | D16: =IF(ISNA(VLOOKUP($B$8&$A15&$B16,KeyFacts_RawData,13,FALSE)),"No data",IF(ISNUMBER(VLOOKUP($B$8&$A15&$B16,KeyFacts_RawData,13,FALSE)),-VLOOKUP($B$8&$A15&$B16,KeyFacts_RawData,13,FALSE),VLOOKUP($B$8&$A15&$B16,KeyFacts_RawData,13,FALSE))) -> #REF! | E16: =IF(ISNA(VLOOKUP(Reference!$AA$2&Reference!$AA$2&$A$15&B16,KeyFacts_RawData,11,FALSE)),"No data",IF(VLOOKUP(Reference!$AA$2&Reference!$AA$2&$A$15&B16,KeyFacts_RawData,11,FALSE)="*",NA(),VLOOKUP(Reference!$AA$2&Reference!$AA$2&$A$15&B16,KeyFacts_RawData,11,FALSE))) -> #REF! | F16: =IF(ISNA(VLOOKUP(Reference!$AA$2&Reference!$AA$2&$A$15&$B16,KeyFacts_RawData,13,FALSE)),"No data",IF(VLOOKUP(Reference!$AA$2&Reference!$AA$2&$A$15&$B16,KeyFacts_RawData,13,FALSE) = "*",NA(),IF(ISNUMBER(VLOOKUP(Reference!$AA$2&Reference!$AA$2&$A$15&$B16,KeyFacts_RawData,13,FALSE)),-VLOOKUP(Reference!$AA$2&Reference!$AA$2&$A$15&$B16,KeyFacts_RawData,13,FALSE),VLOOKUP(Reference!$AA$2&Reference!$AA$2&$A$15&$B16,KeyFacts_RawData,13,FALSE)))) -> #REF! | G16: 4.5 | H16: =IF(ISNA(VLOOKUP($B$8&$A15&$B16,KeyFacts_RawData,7,FALSE)),"No data",VLOOKUP($B$8&$A15&$B16,KeyFacts_RawData,7,FALSE)) -> #REF! | I16: =IF(ISNA(VLOOKUP($B$8&$A15&$B16,KeyFacts_RawData,9,FALSE)),"No data",VLOOKUP($B$8&$A15&$B16,KeyFacts_RawData,9,FALSE)) -> #REF!
